<?xml version="1.0" encoding="UTF-8"?>
<testng-results skipped="0" failed="2" ignored="0" total="2" passed="0">
  <reporter-output>
  </reporter-output>
  <suite name="Suite" duration-ms="44377" started-at="2019-07-31T20:35:08Z" finished-at="2019-07-31T20:35:53Z">
    <groups>
    </groups>
    <test name="Test" duration-ms="44377" started-at="2019-07-31T20:35:08Z" finished-at="2019-07-31T20:35:53Z">
      <class name="Framework.FaceBokTest">
        <test-method status="FAIL" signature="TestFireFox(java.lang.String, java.lang.String)[pri:0, instance:Framework.FaceBokTest@2c6a3f77]" name="TestFireFox" duration-ms="20133" started-at="2019-07-31T16:35:09Z" data-provider="testdata" finished-at="2019-07-31T16:35:29Z">
          <params>
            <param index="0">
              <value>
                <![CDATA[Selenium1@gmail.com]]>
              </value>
            </param>
            <param index="1">
              <value>
                <![CDATA[Password1]]>
              </value>
            </param>
          </params>
          <exception class="java.lang.AssertionError">
            <message>
              <![CDATA[expected [true] but found [false]]]>
            </message>
            <full-stacktrace>
              <![CDATA[java.lang.AssertionError: expected [true] but found [false]
	at org.testng.Assert.fail(Assert.java:94)
	at org.testng.Assert.failNotEquals(Assert.java:513)
	at org.testng.Assert.assertTrue(Assert.java:42)
	at org.testng.Assert.assertTrue(Assert.java:52)
	at Framework.FaceBokTest.TestFireFox(FaceBokTest.java:60)
	at sun.reflect.NativeMethodAccessorImpl.invoke0(Native Method)
	at sun.reflect.NativeMethodAccessorImpl.invoke(Unknown Source)
	at sun.reflect.DelegatingMethodAccessorImpl.invoke(Unknown Source)
	at java.lang.reflect.Method.invoke(Unknown Source)
	at org.testng.internal.MethodInvocationHelper.invokeMethod(MethodInvocationHelper.java:104)
	at org.testng.internal.Invoker.invokeMethod(Invoker.java:645)
	at org.testng.internal.Invoker.invokeTestMethod(Invoker.java:851)
	at org.testng.internal.Invoker.invokeTestMethods(Invoker.java:1177)
	at org.testng.internal.TestMethodWorker.invokeTestMethods(TestMethodWorker.java:129)
	at org.testng.internal.TestMethodWorker.run(TestMethodWorker.java:112)
	at org.testng.TestRunner.privateRun(TestRunner.java:756)
	at org.testng.TestRunner.run(TestRunner.java:610)
	at org.testng.SuiteRunner.runTest(SuiteRunner.java:387)
	at org.testng.SuiteRunner.runSequentially(SuiteRunner.java:382)
	at org.testng.SuiteRunner.privateRun(SuiteRunner.java:340)
	at org.testng.SuiteRunner.run(SuiteRunner.java:289)
	at org.testng.SuiteRunnerWorker.runSuite(SuiteRunnerWorker.java:52)
	at org.testng.SuiteRunnerWorker.run(SuiteRunnerWorker.java:86)
	at org.testng.TestNG.runSuitesSequentially(TestNG.java:1293)
	at org.testng.TestNG.runSuitesLocally(TestNG.java:1218)
	at org.testng.TestNG.runSuites(TestNG.java:1133)
	at org.testng.TestNG.run(TestNG.java:1104)
	at org.testng.remote.RemoteTestNG.run(RemoteTestNG.java:113)
	at org.testng.remote.RemoteTestNG.initAndRun(RemoteTestNG.java:206)
	at org.testng.remote.RemoteTestNG.main(RemoteTestNG.java:177)
]]>
            </full-stacktrace>
          </exception> <!-- java.lang.AssertionError -->
          <reporter-output>
          </reporter-output>
        </test-method> <!-- TestFireFox -->
        <test-method status="PASS" signature="tearDown(org.testng.ITestResult)[pri:0, instance:Framework.FaceBokTest@2c6a3f77]" name="tearDown" is-config="true" duration-ms="4014" started-at="2019-07-31T16:35:29Z" finished-at="2019-07-31T16:35:33Z">
          <params>
            <param index="0">
              <value>
                <![CDATA[[TestResult name=TestFireFox status=FAILURE method=FaceBokTest.TestFireFox(java.lang.String, java.lang.String)[pri:0, instance:Framework.FaceBokTest@2c6a3f77] output={null}]]]>
              </value>
            </param>
          </params>
          <reporter-output>
          </reporter-output>
        </test-method> <!-- tearDown -->
        <test-method status="FAIL" signature="TestFireFox(java.lang.String, java.lang.String)[pri:0, instance:Framework.FaceBokTest@2c6a3f77]" name="TestFireFox" duration-ms="15627" started-at="2019-07-31T16:35:33Z" data-provider="testdata" finished-at="2019-07-31T16:35:48Z">
          <params>
            <param index="0">
              <value>
                <![CDATA[Selenium2@gmail.com]]>
              </value>
            </param>
            <param index="1">
              <value>
                <![CDATA[Password2]]>
              </value>
            </param>
          </params>
          <exception class="java.lang.AssertionError">
            <message>
              <![CDATA[expected [true] but found [false]]]>
            </message>
            <full-stacktrace>
              <![CDATA[java.lang.AssertionError: expected [true] but found [false]
	at org.testng.Assert.fail(Assert.java:94)
	at org.testng.Assert.failNotEquals(Assert.java:513)
	at org.testng.Assert.assertTrue(Assert.java:42)
	at org.testng.Assert.assertTrue(Assert.java:52)
	at Framework.FaceBokTest.TestFireFox(FaceBokTest.java:60)
	at sun.reflect.NativeMethodAccessorImpl.invoke0(Native Method)
	at sun.reflect.NativeMethodAccessorImpl.invoke(Unknown Source)
	at sun.reflect.DelegatingMethodAccessorImpl.invoke(Unknown Source)
	at java.lang.reflect.Method.invoke(Unknown Source)
	at org.testng.internal.MethodInvocationHelper.invokeMethod(MethodInvocationHelper.java:104)
	at org.testng.internal.Invoker.invokeMethod(Invoker.java:645)
	at org.testng.internal.Invoker.invokeTestMethod(Invoker.java:851)
	at org.testng.internal.Invoker.invokeTestMethods(Invoker.java:1177)
	at org.testng.internal.TestMethodWorker.invokeTestMethods(TestMethodWorker.java:129)
	at org.testng.internal.TestMethodWorker.run(TestMethodWorker.java:112)
	at org.testng.TestRunner.privateRun(TestRunner.java:756)
	at org.testng.TestRunner.run(TestRunner.java:610)
	at org.testng.SuiteRunner.runTest(SuiteRunner.java:387)
	at org.testng.SuiteRunner.runSequentially(SuiteRunner.java:382)
	at org.testng.SuiteRunner.privateRun(SuiteRunner.java:340)
	at org.testng.SuiteRunner.run(SuiteRunner.java:289)
	at org.testng.SuiteRunnerWorker.runSuite(SuiteRunnerWorker.java:52)
	at org.testng.SuiteRunnerWorker.run(SuiteRunnerWorker.java:86)
	at org.testng.TestNG.runSuitesSequentially(TestNG.java:1293)
	at org.testng.TestNG.runSuitesLocally(TestNG.java:1218)
	at org.testng.TestNG.runSuites(TestNG.java:1133)
	at org.testng.TestNG.run(TestNG.java:1104)
	at org.testng.remote.RemoteTestNG.run(RemoteTestNG.java:113)
	at org.testng.remote.RemoteTestNG.initAndRun(RemoteTestNG.java:206)
	at org.testng.remote.RemoteTestNG.main(RemoteTestNG.java:177)
]]>
            </full-stacktrace>
          </exception> <!-- java.lang.AssertionError -->
          <reporter-output>
          </reporter-output>
        </test-method> <!-- TestFireFox -->
        <test-method status="PASS" signature="tearDown(org.testng.ITestResult)[pri:0, instance:Framework.FaceBokTest@2c6a3f77]" name="tearDown" is-config="true" duration-ms="4335" started-at="2019-07-31T16:35:48Z" finished-at="2019-07-31T16:35:53Z">
          <params>
            <param index="0">
              <value>
                <![CDATA[[TestResult name=TestFireFox status=FAILURE method=FaceBokTest.TestFireFox(java.lang.String, java.lang.String)[pri:0, instance:Framework.FaceBokTest@2c6a3f77] output={null}]]]>
              </value>
            </param>
          </params>
          <reporter-output>
          </reporter-output>
        </test-method> <!-- tearDown -->
      </class> <!-- Framework.FaceBokTest -->
    </test> <!-- Test -->
  </suite> <!-- Suite -->
</testng-results>
